Workbook

Sheet Check list
B1: 使用说明： | C1: 1、在下方表格中填入对应膜度、RF trim信息并选择好需要的路径，Recipe和Trim信息会自动生成并填入第2页Runcard中，不需要的步骤背景会变黄色、文本变红色并加删除线作为区分；
C2: 2、此表格及生成的runcard给到工艺部门确定，工艺部门需要修改的recipe信息填写到“PE correct框中”，修改的recipe信息会自动更新到第二页Run card模板中；
C3: 3、将第二页需要的步骤（通过列筛选-颜色筛选-按文字颜色筛选-选择黑色）复制并“选择性粘贴--粘贴为数值”到《runcard导入模板》中，最后将其导入到MES中即可完成flow创建。
B5: Mask family name： | D5: EF041A | E5: ( sample:EF030A) | I5: 颜色 | J5: 含义 | M5: Sc Percentage | N5: Code
B6: Production name: | D6: FQ003WM2A001 | E6: Technical version: | F6: E001 | J6: Owner修改区域 | M6: 0 | N6: AN
B7: Select Tx/Rx： | C7: Rx | D7: Production flow name： | E7: ="F"&IF(C7="Tx","T","R")&RIGHT(D6,10)&F6 -> FR003WM2A001E001 | J7: 计算结果或基本不变，可修改 | M7: 0.08 | N7: AS
J8: 工艺部门需要更改的recipe填在此处 | M8: 0.13 | N8: SB
B9: V1 Sc percentage: | D9: 0 | E9: Sc% code: | F9: =VLOOKUP(D9,$M$6:$N$15,2,FALSE) -> AN | I9: 其他白色区域 | J9: 自动更正，不可修改 | M9: 0.2 | N9: SD
B10: V2 Sc percentage: | D10: 0 | E10: Sc% code: | F10: =VLOOKUP(D10,$M$6:$N$15,2,FALSE) -> AN | J10: 默认无内容，不可修改 | M10: 0.25 | N10: SE
M11: A | N11: SF
B12: Layer No. | C12: Route Select | D12: Target THK(nm) | E12: Dep recipe confirm | G12: Photo recipe | I12: Etch /Trim recipe & PR THK confirm | M12: B | N12: SG
E13: Template | F13: PE correct | G13: Template | H13: PE correct | I13: Template | J13: PE correct | K13: Suggest PR THK | M13: C | N13: SH
B14: S1 | D14: 1000 | E14: =IF(F14="","CVD-S1OX"&$D$14,F14) -> CVD-S1OX1000 | G14: =IF(H14="","IP30S1@"&D5&"-08",H14) -> IP30S1@EF041A-08 | I14: =IF(J14="","ICP-S1OX"&$D$14,J14) -> ICP-S1OX1000
B15: U1 | D15: 348 | E15: =IF(F15="","PVD-U1MO"&$D$15&"N",F15) -> PVD-U1MO348N | G15: =IF(H15="","IP3000@"&D5&"-95",H15) -> IP40U1@EF041A-95 | H15: IP40U1@EF041A-95 | I15: =IF(J15="","ICP-U1MO"&$D$15&"N",J15) -> ICP-U1MO348N | K15: 4
B16: V1 | D16: 1100 | E16: =IF(F16="","PVD-V1"&$F$9&$D$16&"N",F16) -> PVD-V1AN1100N | G16: =IF(H16="","IP30V1@"&D5&"-97",H16) -> IP40V1@EF041A-97 | H16: IP40V1@EF041A-97 | I16: =IF(J16="","ICP-V1OX"&$D$18&"N",J16) -> ICP-V1OX200N
I17: =IF(J17="","ICP-V1"&$F$9&$D$16&"N",J17) -> ICP-V1AN1100N | K17: 4
B18: B1 | C18: Yes | D18: 200 | E18: =IF(F18="","CVD-B1OX"&$D$18&"N",F18) -> CVD-B1OX200N | G18: =IF(H18="","IP2000@"&D5&"-42",H18) -> IP2000@EF041A-42 | I18: =IF(J18="","ICP-B1OX"&$D$18&"N",J18) -> ICP-B1OX200N
B19: M2_TF | D19: 368 | E19: =IF(F19="","PVD-M2MO"&$D$19&"N",F19) -> PVD-M2MO368N
B20: UVM1 | C20: No | D20: 060 | G20: =IF(H20="","IP3000@"&D5&"-140",H20) -> IP3000@EF041A-140 | I20: =IF(J20="","TRM-MO280N-A",J20) -> TRM-MO280N-A
B21: F1 | C21: No | D21: 070 | E21: =IF(F21="","PVD-F1MO"&$D$21&"N",F21) -> PVD-F1MO070N | G21: =IF(H21="","IP3000@"&D5&"-45",H21) -> IP3000@EF041A-45 | I21: =IF(J21="",IF(C21="Trim","TRM-MO280N-A","ICP-F1MO"&RIGHT(D21,2)&"N"),J21) -> ICP-F1MO70N
B22: PreM2 | C22: Trim | D22: 058 | G22: =IF(H22="","IP3000@"&D5&"-09",H22) -> IP3000@EF041A-09 | I22: =IF(J22="","TRM-MO280N-A",J22) -> TRM-MO280N-A
B23: PreM3 | C23: No | D23: 011 | G23: =IF(H23="","IP3000@"&D5&"-10",H23) -> IP3000@EF041A-10 | I23: =IF(J23="","TRM-MO280N-A",J23) -> TRM-MO280N-A
B24: T1 | C24: Trim | D24: 010 | G24: =IF(H24="","IP3000@"&D5&"-35",H24) -> IP3000@EF041A-35 | I24: =IF(J24="","TRM-MO280N-A",J24) -> TRM-MO280N-A
B25: T2 | C25: Trim | D25: 015 | G25: =IF(H25="","IP3000@"&D5&"-36",H25) -> IP3000@EF041A-36 | I25: =IF(J25="","TRM-MO280N-A",J25) -> TRM-MO280N-A
B26: T3 | C26: No | D26: 010 | G26: =IF(H26="","IP3000@"&D5&"-135",H26) -> IP3000@EF041A-135 | I26: =IF(J26="","TRM-MO280N-A",J26) -> TRM-MO280N-A
B27: T4 | C27: No | D27: 010 | G27: =IF(H27="","IP3000@"&D5&"-136",H27) -> IP3000@EF041A-136 | I27: =IF(J27="","TRM-MO280N-A",J27) -> TRM-MO280N-A
B28: T5 | C28: No | D28: 015 | G28: =IF(H28="","IP3000@"&D5&"-137",H28) -> IP3000@EF041A-137 | I28: =IF(J28="","TRM-MO280N-A",J28) -> TRM-MO280N-A
B29: T6 | C29: No | D29: 020 | G29: =IF(H29="","IP3000@"&D5&"-138",H29) -> IP3000@EF041A-138 | I29: =IF(J29="","TRM-MO280N-A",J29) -> TRM-MO280N-A
B30: T7 | C30: No | D30: 030 | G30: =IF(H30="","IP3000@"&D5&"-139",H30) -> IP3000@EF041A-139 | I30: =IF(J30="","TRM-MO280N-A",J30) -> TRM-MO280N-A
B31: T8 | C31: No | D31: 040 | G31: =IF(H31="","IP3000@"&D5&"-150",H31) -> IP3000@EF041A-150 | I31: =IF(J31="","TRM-MO280N-A",J31) -> TRM-MO280N-A
B32: M1 | C32: Refer to W1 | D32: =D19 -> 368 | G32: =IF(H32="","IP3000@"&D5&"-126",H32) -> IP3000@EF041A-126 | I32: =IF(J32="","ICP-M1MOPHYS",J32) -> ICP-M1MO368N | J32: ICP-M1MO368N
I33: =IF(J33="","ICP-M1MOCHEM",J33) -> 删除 | J33: 删除
B34: W1 | C34: No | G34: =IF(H34="","IP4000@"&D5&"-126",H34) -> IP4000@EF041A-126 | I34: =IF(J34="","ICP-V2"&$F$10&$D$36&"N",J34) -> ICP-V2AN300N
I35: =IF(J35="","ICP-W1MO"&$D$32&"N",J35) -> ICP-W1MO368N
B36: V2 | D36: 300 | E36: =IF(F36="","PVD-V2"&$F$10&$D$36&"N",F36) -> PVD-V2AN300N | G36: =IF(H36="","IP3000@"&D5&"-90",H36) -> IP3000@EF041A-90 | I36: =IF(J36="","ICP-V2"&$F$10&$D$36&"N",J36) -> ICP-V2AN300N
B37: Pad | D37: 2000/100 | E37: =IF(F37="","EGN-AL2000-A",F37) -> EGN-AL2000-A | G37: =IF(H37="","IN3000@"&D5&"-48",H37) -> IN3000@EF041A-48 | I37: =IF(J37="","ETCHLIF-PAD1",J37) -> ETCHLIF-PAD1
B38: V3 | D38: =D16+D36+60 -> 1460 | G38: =IF(H38="","IP4000@"&D5&"-58",H38) -> IP4000@EF041A-58 | I38: =IF(J38="","ICP-V3"&$F$9&$D$38,J38) -> ICP-V3AN1460
B39: Grinding | D39: 250um | E39: =IF(F39="","WBG-140-"&LEFT(D39,3),F39) -> WBG-140-250
B40: Thin RF Trim | C40: Yes | I40: =IF(J40="","TRM-AN300N-C",J40) -> TRM-AN300N-C
B42: Trim route: | C42: Trim time | D42: Frequency base | E42: 1st Trim Target | F42: 2nd Trim Target | G42: 3rd Trim Target | H42: 4th Trim Target | I42: A-Trim slope | J42: B-Trim intercept
...

Sheet Runcard-template
A1: YANXIMC Runcard产品流程信息
B3: 产品号(*) | C3: ='Check list'!D6 -> FQ003WM2A001 | D3: 工艺流程号(*) | E3: ='Check list'!E7 -> FR003WM2A001E001
A5: 工艺流程号(*) | B5: 路径号(*) | C5: 步骤号(*) | D5: 步骤描述(*) | E5: TARGET | F5: SPC JOB ID | G5: RECIPE ID(*) | H5: 设备组ID(*) | I5: 设备ID | J5: 光罩族ID | K5: 光罩ID | L5: EDC参数集ID | M5: Q-TIME | N5: Q-TIME ID | O5: 返工流程ID | P5: 返回工步号 | Q5: 路径分支(0,1,不选) | R5: 步骤分支(0,1,不选) | S5: 操作提示 | T5: 操作类型
A6: =$E$3 -> FR003WM2A001E001 | B6: WAFER START | C6: 010020 | D6: Wafer start | G6: NA | H6: NA
A7: =$E$3 -> FR003WM2A001E001 | B7: LASER MARK | C7: 010040 | D7: Laser mark | G7: WFM-MAKHIM01 | H7: AWFM
A8: =$E$3 -> FR003WM2A001E001 | B8: S1 | C8: 020020 | D8: Pre-Stress monitor wafer | G8: NA | H8: ASTR | L8: ETD_TF_WARP_S5
A9: =$E$3 -> FR003WM2A001E001 | B9: S1 | C9: 020040 | D9: Wafer clean before S1 dep | G9: WETSTD-CLEAN | H9: AACW | M9: 72:00:00 | N9: ="ETD_S10001_"&'Check list'!E7 -> ETD_S10001_FR003WM2A001E001
A10: =$E$3 -> FR003WM2A001E001 | B10: S1 | C10: 020060 | D10: Bare wafer particle monitor | G10: PAC-SIOP3UMO | H10: APAC | L10: ETD_MFG_WPA_A | O10: ETD_WTRE0001 | P10: 020040
A11: =$E$3 -> FR003WM2A001E001 | B11: S1 | C11: 020080 | D11: S1 by PECVD | E11: ="PECVD S1 SiO2 "&'Check list'!D14&"nm" -> PECVD S1 SiO2 1000nm | G11: ='Check list'!E14 -> CVD-S1OX1000 | H11: ACVD | M11: 72:00:00 | N11: ="ETD_S10002_"&'Check list'!E7 -> ETD_S10002_FR003WM2A001E001 | O11: ETD_WTRE0001 | P11: 020040
A12: =$E$3 -> FR003WM2A001E001 | B12: S1 | C12: 020100 | D12: THK monitor 49points | E12: ="THK S1 SiO2 "&'Check list'!D14&"nm" -> THK S1 SiO2 1000nm | G12: ="THK-S1OX"&'Check list'!D14 -> THK-S1OX1000 | H12: ATHK | L12: ETD_TF_S1THK_HMT
A13: =$E$3 -> FR003WM2A001E001 | B13: S1 | C13: 020120 | D13: Post stress S1 monitor wafer | G13: NA | H13: ASTR | L13: ETD_TF_S1STRESS_T
A14: =$E$3 -> FR003WM2A001E001 | B14: S1 | C14: 020140 | D14: Roughness monitor 1point | G14: NA | H14: AAFM | L14: ETD_TF_S1RA_S5
A15: =$E$3 -> FR003WM2A001E001 | B15: S1 | C15: 020160 | D15: Monitor wafer split | G15: NA | H15: NA
A16: =$E$3 -> FR003WM2A001E001 | B16: S1 | C16: 020180 | D16: Wafer clean | G16: WETDIW-CLEAN | H16: AWET | M16: 72:00:00 | N16: ="ETD_S10003_"&'Check list'!E7 -> ETD_S10003_FR003WM2A001E001
A17: =$E$3 -> FR003WM2A001E001 | B17: S1 | C17: 020200 | D17: S1 Photolithography | G17: ='Check list'!G14 -> IP30S1@EF041A-08 | H17: AILI | J17: ='Check list'!$D$5&"_08" -> EF041A_08 | M17: 72:00:00 | N17: ="ETD_S10004_"&'Check list'!E7 -> ETD_S10004_FR003WM2A001E001 | O17: ETD_WTRE0001 | P17: 020180
A18: =$E$3 -> FR003WM2A001E001 | B18: S1 | C18: 020220 | D18: Photo S1 TCD measure 5points | G18: ='Check list'!$D$5&"/"&'Check list'!$D$5&"_S1_PH_T" -> EF041A/EF041A_S1_PH_T | H18: ACDS | L18: ETD_PH_S1TCD_SCD | O18: ETD_PRRE0001 | P18: 020180
A19: =$E$3 -> FR003WM2A001E001 | B19: S1 | C19: 020240 | D19: Photo S1 BCD measure 5points | G19: ='Check list'!$D$5&"/"&'Check list'!$D$5&"_S1_PH_B" -> EF041A/EF041A_S1_PH_B | H19: ACDS | L19: ETD_PH_S1BCD_SCD | O19: ETD_PRRE0001 | P19: 020180
A20: =$E$3 -> FR003WM2A001E001 | B20: S1 | C20: 020260 | D20: ADI check | G20: NA | H20: AADI | O20: ETD_PRRE0001 | P20: 020180
A21: =$E$3 -> FR003WM2A001E001 | B21: S1 | C21: 020280 | D21: S1 Etch | E21: ="ETCH S1 SiO2 "&'Check list'!D14&"nm" -> ETCH S1 SiO2 1000nm | G21: ='Check list'!I14 -> ICP-S1OX1000 | H21: ACVD | M21: 12:00:00 | N21: ="ETD_S10005_"&'Check list'!E7 -> ETD_S10005_FR003WM2A001E001
A22: =$E$3 -> FR003WM2A001E001 | B22: S1 | C22: 020300 | D22: Ashing | G22: ASH-AS1-002M | H22: AASH | M22: 12:00:00 | N22: ="ETD_S10006_"&'Check list'!E7 -> ETD_S10006_FR003WM2A001E001 | O22: ETD_ETRE0001 | P22: 020300
A23: =$E$3 -> FR003WM2A001E001 | B23: S1 | C23: 020320 | D23: Wet PR strip | G23: WETPR-REMOVE | H23: ASSW
A24: =$E$3 -> FR003WM2A001E001 | B24: S1 | C24: 020340 | D24: Etch S1 THK measure 13points | G24: ="PRF-"&'Check list'!$D$5&"S1" -> PRF-EF041AS1 | H24: APRF | L24: ETD_ET_S1THK_S5 | M24: 84:00:00 | N24: ="ETD_S10007_"&'Check list'!E7 -> ETD_S10007_FR003WM2A001E001 | O24: ETD_PERE0001 | P24: 020300
A25: =$E$3 -> FR003WM2A001E001 | B25: S1 | C25: 020360 | D25: Etch S1 TCD measure 5points | G25: ='Check list'!$D$5&"/"&'Check list'!$D$5&"_S1_ET_T" -> EF041A/EF041A_S1_ET_T | H25: ACDS | L25: ETD_ET_S1TCD_SCD | O25: ETD_PERE0001 | P25: 020300
A26: =$E$3 -> FR003WM2A001E001 | B26: S1 | C26: 020380 | D26: Etch S1 BCD measure 5points | G26: ='Check list'!$D$5&"/"&'Check list'!$D$5&"_S1_ET_B" -> EF041A/EF041A_S1_ET_B | H26: ACDS | L26: ETD_ET_S1BCD_SCD | O26: ETD_PERE0001 | P26: 020300
A27: =$E$3 -> FR003WM2A001E001 | B27: S1 | C27: 020400 | D27: AEI check | G27: NA | H27: AADI | O27: ETD_PERE0001 | P27: 020300
A28: =$E$3 -> FR003WM2A001E001 | B28: S1 | C28: 020420 | D28: DFI check | G28: NA | H28: ADFI | O28: ETD_PRRE0003 | P28: 020420
A29: =$E$3 -> FR003WM2A001E001 | B29: U1 | C29: 040020 | D29: Monitor wafer merge | G29: NA | H29: NA
A30: =$E$3 -> FR003WM2A001E001 | B30: U1 | C30: 040040 | D30: Wafer clean | G30: WETDIW-CLEAN | H30: AWET | M30: 72:00:00 | N30: ="ETD_U10001_"&'Check list'!E7 -> ETD_U10001_FR003WM2A001E001
A31: =$E$3 -> FR003WM2A001E001 | B31: U1 | C31: 040060 | D31: U1 By PVD | E31: ="PVD U1 Mo/AlN "&'Check list'!D15&"/60nm" -> PVD U1 Mo/AlN 348/60nm | G31: ='Check list'!E15 -> PVD-U1MO348N | H31: APVD | M31: 84:00:00 | N31: ="ETD_U10007_"&'Check list'!E7 -> ETD_U10007_FR003WM2A001E001 | O31: ETD_WTRE0001 | P31: 040040
A32: =$E$3 -> FR003WM2A001E001 | B32: U1 | C32: 040120 | D32: Post-Stress U1 monitor wafer | G32: NA | H32: ASTR | L32: ETD_TF_U1STRESS_T
A33: =$E$3 -> FR003WM2A001E001 | B33: U1 | C33: 040140 | D33: Roughness monitor 1point | G33: NA | H33: AAFM | L33: ETD_TF_U1RA_S5
A34: =$E$3 -> FR003WM2A001E001 | B34: U1 | C34: 040160 | D34: XRD monitor 1point | G34: NA | H34: AXRD | L34: ETD_TF_U1FWHM_T
A35: =$E$3 -> FR003WM2A001E001 | B35: U1 | C35: 040180 | D35: Monitor wafer split | G35: NA | H35: NA
A36: =$E$3 -> FR003WM2A001E001 | B36: U1 | C36: 040190 | D36: U1 THK measurement | E36: ="THK U1 Mo "&'Check list'!D15&"nm" -> THK U1 Mo 348nm | G36: ="MTH-"&'Check list'!$D$5&"U1" -> MTH-EF041AU1 | H36: AMTH | L36: ETD_TF_U1THK_S5
A37: =$E$3 -> FR003WM2A001E001 | B37: U1 | C37: 040200 | D37: Wafer clean | G37: WETDIW-CLEAN | H37: AWET | M37: 72:00:00 | N37: ="ETD_U10002_"&'Check list'!E7 -> ETD_U10002_FR003WM2A001E001
A38: =$E$3 -> FR003WM2A001E001 | B38: U1 | C38: 040220 | D38: U1 Photolithography | G38: ='Check list'!G15 -> IP40U1@EF041A-95 | H38: AILI | J38: ='Check list'!$D$5&"_95" -> EF041A_95 | M38: 72:00:00 | N38: ="ETD_U10003_"&'Check list'!E7 -> ETD_U10003_FR003WM2A001E001 | O38: ETD_WTRE0001 | P38: 040200
A39: =$E$3 -> FR003WM2A001E001 | B39: U1 | C39: 040240 | D39: Photo U1 TCD measure 5points | G39: ='Check list'!$D$5&"/"&'Check list'!$D$5&"_U1_PH_T" -> EF041A/EF041A_U1_PH_T | H39: ACDS | L39: ETD_PH_U1TCD_SCD | O39: ETD_PRRE0002 | P39: 040200
A40: =$E$3 -> FR003WM2A001E001 | B40: U1 | C40: 040260 | D40: Photo U1 BCD measure 5points | G40: ='Check list'!$D$5&"/"&'Check list'!$D$5&"_U1_PH_B" -> EF041A/EF041A_U1_PH_B | H40: ACDS | L40: ETD_PH_U1BCD_SCD | O40: ETD_PRRE0002 | P40: 040200
A41: =$E$3 -> FR003WM2A001E001 | B41: U1 | C41: 040280 | D41: OVL measure | G41: ="OVL"&'Check list'!$D$5&"-95" -> OVLEF041A-95 | H41: AOVL | L41: ETD_PH_U1OVL_S5 | O41: ETD_PRRE0002 | P41: 040200
A42: =$E$3 -> FR003WM2A001E001 | B42: U1 | C42: 040300 | D42: ADI check | G42: NA | H42: AADI | O42: ETD_PRRE0002 | P42: 040200
...

Sheet Layer mask及简写
B3: 路径号 | C3: Rcp简写 | D3: 路径编码
B4: WAFER START | D4: 010
B5: LASER MARK | D5: 010
B6: S1 | C6: S1 | D6: 020
B7: U1 | C7: U1 | D7: 040
B8: V1_TF | C8: V1 | D8: 060
B9: B1_TF | C9: B1 | D9: 080
B10: V1 | C10: V1 | D10: 100
B11: B1 | C11: B1 | D11: 120
B12: F1(Dep+etch) | C12: F1 | D12: 130
B13: M2_TF | C13: M2 | D13: 140
B14: UVM1 | C14: UM | D14: 150
B15: F1(Trim) | D15: 160
B16: PRE_M2 | C16: PM | D16: 180
B17: PRE_M3 | C17: P3 | D17: 190
B18: T1 | C18: T1 | D18: 200
B19: T2 | C19: T2 | D19: 220
B20: T3 | C20: T3 | D20: 240
B21: T4 | C21: T4 | D21: 260
B22: T5 | C22: T5 | D22: 280
B23: T6 | C23: T6 | D23: 285
B24: T7 | C24: T7 | D24: 290
B25: T8 | C25: T8 | D25: 295
B26: M1 | C26: M1 | D26: 300
B27: V2_TF | C27: V2 | D27: 320
... B31: D1 | C31: D1 | D31: 400
B32: 1ST REL_ET | D32: 420
B33: THICK RF TRIM | D33: 440
B34: PS | C34: PS | D34: 450
B35: V3 | C35: V3 | D35: 460
B36: E-LOT REL_ET | D36: 480
B37: E-LOT RF TRIM | D37: 500
B38: GRIND | D38: 520
B39: Thin REL_ET | D39: 530
B40: 2nd REL_ET | D40: 540
B41: THIN RF TRIM | D41: 560
B42: PKG PREPARE | D42: 580
B43: Lot judgement | D43: 900

Sheet 更新内容
A1: V6.4.1更新内容
A2: 1、取消D1及厚片Rls，厚片Trim
A3: 2、取消E lot厚片3次Trim，统一到薄片Trim
A4: 3、S1/B1，V1-SiO2蚀刻绑定机台从AICP更改为ACVD
A5: 4、rls etch修改为薄片制程，包括边缘目检-翘曲度测试-rls-AEI检测，翘曲度增加EDC收集
A6: 5、RF Trim改成薄片制程，每一次Trim前增加外观目检站点
A7: 6、每一次RF量测增加EDC数据收集，方便后续SPC管控
A10: 1、UVM1 layer简写UM，来match recipe命名规则，建议后续不要按照此规则命名，可以用现有未使用的字母来命名，或者两个字母组合，不然可能带来recipe名称重复；
A11: 2、P1 layer目前用在Pad layer简写中，暂定修改为PS layer；
A12: 3、Trim之后不需要量测CD，步骤取消
A13: 4、UVM1 Trim photo CD修改为量测BCD；
A14: 5、PreM2 layer recipe命名简写为PM，PreM3目前只能简写为P3，更Pad-P1容易混淆，建议后面超过两个字的字母不要重复，或者数字区分；
... A36: 6、减薄后的厚度量测增加EDC参数集ID：ETD_TF_250THK_HMT
